Workbook
Name _Toc58394808: 'Testing Requirements'!#REF!
Name _Toc58394817: 'Testing Requirements'!#REF!
Name PLAN_DATE: #REF!
Name PLAN_DATE: #REF!
Name REPORT_DATE: #REF!
Name REPORT_DATE: #REF!
Name Status1: [1]Data!$A$1:$C$1
Name Status2: [1]Data!$A$2:$C$2
Name VALIDATION_REPORT_DATE: #REF!
Name VALIDATION_REPORT_DATE: #REF!
Name PLAN_DATE: #REF!
Name REPORT_DATE: #REF!
Name Status1: [2]Data!$A$1:$C$1
Name Status2: [2]Data!$A$2:$C$2
Name VALIDATION_REPORT_DATE: #REF!

Sheet PVP&R
A1: JLR DESIGN/PRODUCTION VERIFICATION FLOW CHART | J1: DVP NUMBER | P1: DEPT / NAME | U1: Start date
J2: PLAN DATE | P2: PLAN ORIGINATOR | U2: Week | X2: 7
A3: COMPONENT / ASSEMBLY | C3: Head UP Display (Gen 3) | D3: P/N | E3: T2L2-14F906-BA | J3: CONCURRENCE | P3: MANAGER APPROVAL | U3: TEST TIME IN 2024
A4: MY | B4: 2026 | C4: PROGRAMME | D4: LATEST DESIGN LEVEL | F4: XX | G4: SUPPLIER | H4: CRYSTAL-OPTECH | J4: REPORT DATE | P4: REPORTING ENGR. | U4: =X1 -> 0 | V4: =U4+$X$2 -> 7 | W4: =V4+$X$2 -> 14 | X4: =W4+$X$2 -> 21 | Y4: =X4+$X$2 -> 28 | Z4: =Y4+$X$2 -> 35 | AA4: =Z4+$X$2 -> 42 | AB4: =AA4+$X$2 -> 49 | AC4: =AB4+$X$2 -> 56 | ... AO4: =AN4+$X$2 -> 140
A5: TEST PLAN | P5: TEST REPORT | T5: NOTES
A6: ITEM | B6: PROCEDURE | C6: TEST ITEM | D6: TEST / | E6: TEST DESCRIPTION | F6: ACCEPTANCE | G6: TARGET | H6: TEST | I6: TEST | J6: SAMPLE | K6: TYPICAL | L6: START DATE | N6: COMPLETION DATE | P6: SAMPLE | S6: ACTUAL
A7: No. | B7: STANDARD | D7: NO TEST | F7: CRITERIA | G7: REQUIREMENTS | H7: RESPONSIBILITY | I7: STAGE | J7: QTY. | K7: DURATION (h) | L7: SCHEDULE | M7: ACTUAL | N7: SCHEDULE | O7: ACTUAL | P7: QTY. | Q7: TYPE | R7: PHASE | S7: RESULTS | U7: 2 | V7: 3 | W7: 4 | X7: 5 | Y7: 6 | Z7: 7 | AA7: 8 | AB7: 9 | AC7: 10 | AD7: 11 | AE7: 12 | AF7: 13 | AG7: 14 | AH7: 15 | AI7: 16 | AJ7: 17 | AK7: 18 | AL7: 19 | AM7: 20 | AN7: 21 | AO7: 22
A8: Performance Evaluation & Functional Evaluation
A9: 1 | B9: TPJLR.13.001 | C9: Optical Test | D9: ='Test Flow chart'!P12 -> Test
A10: 2 | B10: TPJLR.18.125 L1 L4 | C10: Performance Evaluation& Functional Evaluation | D10: ='Test Flow chart'!P12 -> Test
A11: Group A Sequence Tests
A12: A1 | B12: TPJLR.18.125 K1 | C12: Low Temperature Exposure | D12: ='Test Flow chart'!B23 -> Test
A13: A2 | B13: TPJLR.18.125 K2 | C13: High Temperature Exposure | D13: ='Test Flow chart'!B27 -> Test
A14: A3 | B14: TPJLR.18.125 K3 | C14: Low Temperature Operation | D14: ='Test Flow chart'!B31 -> Test
A15: A4 | B15: TPJLR.18.125 K4 | C15: High Temperature Operation | D15: ='Test Flow chart'!B35 -> Test
A16: A5 | B16: TPJLR.18.125 K5 | C16: Temperature Step Test | D16: ='Test Flow chart'!B39 -> Test
A17: A6 | B17: TPJLR.18.125 K6 | C17: Powered Thermal Cycle | D17: ='Test Flow chart'!B43 -> Test
A18: A7 | B18: TPJLR.18.125 K7 | C18: Thermal Shock in Air | D18: ='Test Flow chart'!B47 -> Test
A19: A8 | B19: TPJLR.18.125 L1 L4 | C19: Performance Evaluation& Functional Evaluation | D19: ='Test Flow chart'!B51 -> Test
A20: A9 | B20: TPJLR.18.125 K15 | C20: Vibration | D20: ='Test Flow chart'!B55 -> Test
A21: A10 | B21: TPJLR.18.125 K16.1 | C21: Mechanical Shock-Package Drop | D21: ='Test Flow chart'!B59 -> Test
A22: A11 | B22: TPJLR.18.125 K16.4 | C22: Mechanical Shock-Low | D22: ='Test Flow chart'!B63 -> Test
A23: A12 | B23: TPJLR.18.125 K17 | C23: Audible Noise | D23: ='Test Flow chart'!B67 -> Test
A24: A13 | B24: TPJLR.18.125 K9 | C24: Humidity Temperature Cycle | D24: ='Test Flow chart'!B71 -> Test
A25: A14 | B25: TPJLR.18.125 K10 | C25: Water/Fluid Ingress Tests | D25: ='Test Flow chart'!B75 -> Test
A26: A15 | B26: TPJLR.18.125 K13 | C26: Dust Ingress | D26: ='Test Flow chart'!B79 -> Test
A27: A16 | B27: TPJLR.18.125 K14 | C27: Dust Blowing | D27: ='Test Flow chart'!B83 -> No Test
A28: A17 | B28: TPJLR.18.125 L1 L4 | C28: Performance Evaluation& Functional Evaluation | D28: ='Test Flow chart'!B87 -> Test
A29: A18 | B29: TPJLR.13.001 | C29: Optical Test | D29: ='Test Flow chart'!B91 -> Test
A30: A19 | B30: TPJLR.18.125 L6 | C30: Internal Inspection | D30: ='Test Flow chart'!B95 -> Test
A31: Group B Sequence Tests
A32: B1 | B32: TPJLR.18.125 K22 | C32: Chemical Resistance | D32: ='Test Flow chart'!H23 -> Test
A33: B2 | B33: TPJLR.18.125 K18 | C33: Connector and lead/lock strength | D33: ='Test Flow chart'!H27 -> Test
A34: B3 | B34: TPJLR.18.125 L1 L4 | C34: Performance Evaluation& Functional Evaluation | D34: ='Test Flow chart'!H31 -> Test
A35: B4 | B35: TPJLR.18.125 L6 | C35: Internal Inspection | D35: ='Test Flow chart'!H35 -> Test
A36: Group C Sequence Tests
A37: C1 | B37: TPJLR.18.125 K7 | C37: Thermal Shock in Air | D37: ='Test Flow chart'!N23 -> Test
A38: C2 | B38: TPJLR.18.125 K15 | C38: Vibration | D38: ='Test Flow chart'!N27 -> Test
A39: C3 | B39: TPJLR.18.125 K13 | C39: Dust Ingress | D39: ='Test Flow chart'!N31 -> Test
A40: C4 | B40: TPJLR.18.125 K14 | C40: Dust Blowing | D40: ='Test Flow chart'!N35 -> No Test
...

Sheet Test Flow chart
G1: JLR DESIGN/PRODUCTION VERIFICATION FLOW CHART
P8: Test | Q8: Optical Test
Q9: TPJLR-13-001& STJLR.13.5009
Q10: Sample No. | R10: 1 | S10: to | T10: =SUM(Y21,Q21,K21,E21) -> 82
P12: Test | Q12: Performance Evaluation & Functional Evaluation
Q13: TPJLR.18.125 | T13: L1 L4
Q14: Sample No. | R14: 1 | S14: to | T14: =SUM(E21,K21,Q21,Y21) -> 82
B18: Group A Sequence Tests | H18: Group B Sequence Tests | N18: Group C Sequence Tests | T18: Group D Parallel Tests | AB18: Group F Other Tests
B21: Total samples | E21: 14 | H21: Total samples | K21: 12 | N21: Total samples | Q21: 6 | T21: Total samples | Y21: 50 | AB21: Total samples | AD21: 26
B23: Test | C23: Low Temperature Exposure | H23: Test | I23: Chemical Resistance | N23: Test | O23: Thermal Shock in Air | T23: D-1 | V23: Test | W23: Corrosive Gases | AB23: Test | AC23: Restricted Substance Management
C24: TPJLR.18.125 | F24: K1 | I24: TPJLR.18.125 | L24: K22 | O24: TPJLR.18.125 | R24: K7 | W24: TPJLR.18.125 | Z24: K21 | AC24: STJLR.99.9999
C25: Sample No. | D25: 1 | E25: to | F25: 12 | I25: Sample No | J25: 15 | K25: to | L25: 26 | O25: Sample No. | P25: 27 | Q25: to | R25: 32 | W25: Sample No. | X25: 33 | Y25: to | Z25: 38 | AC25: Based on actual tests
B27: Test | C27: High Temperature Exposure | H27: Test | I27: Connector and lead/lock strength | N27: Test | O27: Vibration | V27: Test | W27: Performance Evaluation & Functional Evaluation | AB27: Test | AC27: Noise test
C28: TPJLR.18.125 | F28: K2 | I28: TPJLR.18.125 | L28: K18 | O28: TPJLR.18.125 | R28: K15 | W28: TPJLR.18.125 | Z28: L1 L4 | AC28: TPJLR.00.346
C29: Sample No. | D29: 1 | E29: to | F29: 12 | I29: Sample No | J29: 15 | K29: to | L29: 26 | O29: Sample No. | P29: 27 | Q29: to | R29: 32 | W29: Sample No. | X29: 33 | Y29: to | Z29: 38 | AC29: Sample No. | AD29: 83 | AE29: to | AF29: 107
B31: Test | C31: Low Temperature Operation | H31: Test | I31: Performance Evaluation & Functional Evaluation | N31: Test | O31: Dust Ingress | V31: Test | W31: Optical Test
C32: TPJLR.18.125 | F32: K3 | I32: TPJLR.18.125 | L32: L1 L4 | O32: TPJLR.18.125 | R32: K13 | W32: STJLR.13.5009
C33: Sample No. | D33: 1 | E33: to | F33: 12 | I33: Sample No. | J33: 15 | K33: to | L33: 26 | O33: Sample No | P33: 27 | Q33: to | R33: 32 | W33: Sample No. | X33: 33 | Y33: to | Z33: 38
B35: Test | C35: High Temperature Operation | H35: Test | I35: Internal Inspection | N35: No Test | O35: Dust Blowing Test | V35: Test | W35: Internal Inspection
C36: TPJLR.18.125 | F36: K4 | I36: TPJLR.18.125 | L36: L6 | O36: TPJLR.18.125 | R36: K14 | W36: TPJLR.18.125 | Z36: L6
C37: Sample No. | D37: 1 | E37: to | F37: 12 | I37: Sample No. | J37: 15 | K37: to | L37: 26 | O37: Sample No | P37: 27 | Q37: to | R37: 32 | T37: Samples | U37: 6 | W37: Sample No. | X37: 33 | Y37: to | Z37: 38
B39: Test | C39: Temperature Step Test | N39: Test | O39: Mechanical Wear-Out | T39: D-2 | V39: Test | W39: Solar Radiation
C40: TPJLR.18.125 | F40: K5 | O40: TPJLR.18.125 | R40: K26 | W40: TPJLR.18.125 | Z40: K20
C41: Sample No. | D41: 1 | E41: to | F41: 12 | O41: Sample No | P41: 27 | Q41: to | R41: 32 | W41: Sample No. | X41: 39 | Y41: to | Z41: 44
B43: Test | C43: Powered Thermal Cycle | N43: Test | O43: Performance Evaluation & Functional Evaluation | V43: Test | W43: Performance Evaluation & Functional Evaluation
C44: TPJLR.18.125 | F44: K6 | O44: TPJLR.18.125 | R44: L1 L4 | W44: TPJLR.18.125 | Z44: L1 L4
C45: Sample No. | D45: 1 | E45: to | F45: 12 | O45: Sample No. | P45: 27 | Q45: to | R45: 32 | W45: Sample No. | X45: 39 | Y45: to | Z45: 44
B47: Test | C47: Thermal Shock in Air | N47: Test | O47: Optical Test | V47: Test | W47: Optical Test
C48: TPJLR.18.125 | F48: K7 | O48: STJLR.13.5009 | W48: STJLR.13.5009
C49: Sample No. | D49: 1 | E49: to | F49: 12 | O49: Sample No. | P49: 27 | Q49: to | R49: 32 | W49: Sample No. | X49: 39 | Y49: to | Z49: 44
B51: Test | C51: Performance Evaluation & Functional Evaluation | N51: Test | O51: Internal Inspection | V51: Test | W51: Internal Inspection
C52: TPJLR.18.125 | F52: L1 L4 | O52: TPJLR.18.125 | R52: L6 | W52: TPJLR.18.125 | Z52: L6
C53: Sample No. | D53: 1 | E53: to | F53: 12 | O53: Sample No. | P53: 27 | Q53: to | R53: 32 | T53: Samples | U53: 6 | W53: Sample No. | X53: 39 | Y53: to | Z53: 44
B55: Test | C55: Vibration | T55: D-3 only PCBA | V55: Test | W55: Thermal Shock Endurance
C56: TPJLR.18.125 | F56: K15 | W56: TPJLR.18.125 | Z56: K23
C57: Sample No. | D57: 1 | E57: to | F57: 12 | W57: Sample No. | X57: 45 | Y57: to | Z57: 52
B59: Test | C59: Mechanical Shock-Package Drop | V59: Test | W59: Performance Evaluation & Functional Evaluation
C60: TPJLR.18.125 | E60: K14.3/K14.4 | F60: K16.1 | W60: TPJLR.18.125 | Z60: L1 L4
C61: Sample No. | D61: 1 | E61: to | F61: 14 | W61: Sample No. | X61: 45 | Y61: to | Z61: 52
B63: Test | C63: Mechanical Shock-Low | V63: Test | W63: Internal Inspection
...

Sheet Testing Requirements
A1: JLR DESIGN/PRODUCTION VERIFICATION FLOW CHART
A3: TESTING REQUIREMENT
A4: Test temperature and voltage description： | C4: Tmin/TEmin：-40℃ | D4: Vmin：7.5V ±0.2 V
C5: Tpmin：-30℃ | D5: Vpmin：9V ±0.2 V
C6: Tmax=TPmax：85℃ | D6: Vpmax=Vmax：16 ±0.2 V
C7: TEmax：95℃ | D7: VN：13.5 ±0.5 V
C8: TSoak: 85°C
A10: NO. | B10: Test Item | C10: Test Spec | D10: Test Procedure | E10: Requirements or Limits | H10: Remark
E11: L2 | F11: L3 | G11: L5
A12: 1 | B12: K1 Low Temperature Exposure | C12: TPJLR.18.125（Issue 5） Section K1 ISO 16750-4:2010 Section 5.1.1.1 IEC 60068-2-1:2007 (Test Ab) | D12: Stabilize the DUTs at a temperature of -40 °C (TEmin). The rate of temperature change in the chamber shall not exceed 1 °C/min (averaged over a 5 minute period).Expose the DUTs for 24h. The DUTs shall be unpowered. | E12: When the test is complete perform the Functional Check (L 2) at -40 °C (TEmin) Need to meet the requirements of L2 in Testing Evaluation | F12: / | G12: Visual Check (L 5) at room temperature Need to meet the requirements of L5 in Testing Evaluation
A13: 2 | B13: K2 High Temperature Exposure | C13: TPJLR.18.125（Issue 5） Section K2 ISO 16750-4:2010 Section 5.1.2.1 IEC 60068-2-2:2007 (Test Bb) | D13: Stabilize the DUTs at a temperature of 95 °C (TEmax). The rate of temperature change in the chamber shall not exceed 1 °C/min (averaged over a 5 minute period).Expose the DUTs for 24h. The DUTs shall be unpowered. | E13: When the test is complete perform the Functional Check (L 2) at at room temperature Need to meet the requirements of L2 in Testing Evaluation | F13: / | G13: Visual Check (L 5) at room temperature Need to meet the requirements of L5 in Testing Evaluation | H13: When the HUD is in an environment of 95℃, the HUD will be in a sleep state.
A14: 3 | B14: K3 Low Temperature Operation | C14: TPJLR.18.125（Issue 5） Section K3 ISO 16750-4:2010 Section 5.1.1.2 IEC 60068-2-1:2007 (Tests Ad, Ae) | D14: Power up chamber and stabilize at a temperature of -40 °C (Tmin). The rate of temperature change in the chamber shall not exceed 1 °C/min (averaged over a 5 minute period). power cycle:1 minute on - 4 minutes off Perform Monitored Operation on the DUTs as specified in section L 3 during the 24h exposure period. | E14: When the test is complete perform the Functional Check (L 2) at -40 °C (Tmin) Need to meet the requirements of L2 in Testing Evaluation | F14: When the supply voltage of the DUT is within the normal operating voltage range, the DUT should meet the requirements of L3. | G14: Visual Check (L 5) at room temperature Need to meet the requirements of L5 in Testing Evaluation
A15: 4 | B15: K4 High Temperature Operation | C15: TPJLR.18.125（Issue 5） Section K4 ISO 16750-4:2010 Section 5.1.2.2 IEC 60068-2-2:2007 (Test Bd, Be) | D15: Power up chamber and stabilize at a temperature of 85 °C (Tmax/Tpmax).Perform Monitored Operation on the DUTs as specified in section L 3 during the 96h exposure period. Normal Load Stress conditions shall be used. The rate of temperature change in the chamber shall not exceed 1 °C/min averaged over a 5 minute period. | E15: When the test is complete perform the Functional Check (L 2) at Tmax Need to meet the requirements of L2 in Testing Evaluation | F15: The DUT should meet the requirements of L3. | G15: Visual Check (L 5) at room temperature Need to meet the requirements of L5 in Testing Evaluation
A16: 5 | B16: K5 Temperature Step Test | C16: TPJLR.18.125（Issue 5） Section K5 ISO 16750-4:2010 Section 5.2 | D16: a. Power up the chamber and stabilise at 20 °C. Perform a Functional Check as defined in Section L 2 at 9V &16V&13.5N. b. Lower the chamber temperature by 5 °C, and allow the temperature of the DUT to stabilise c. Perform a Functional Check as L 2 at 9V &16V&13.5N Raise the chamber temperature by 5 °C and allow the temperature of the DUT to stabilise d. Repeat steps (b) and (c) until -40 °C is reached e. Raise the chamber temperature by 5 °C and allow the temperature of the DUT to stabilise f. Perform a Functional Check as L 2 at 9V &16V&13.5N g. Repeat steps (e) and (f) until 85 °C Tmax is reached h. Lower the chamber temperature by 5 °C, and allow the DUT temperature to stabilise. i. Perform a Functional Check as L 2 at 9V &16V&13.5N. j. Repeat steps (h) and (i) until 20 °C is reached. k. When the test is complete perform a Visual Check (L 5). | E16: Need to meet the requirements of L2 in Testing Evaluation | F16: The DUT should meet the requirements of L3. During the test, the tester is required to visually display the image of the sample at all times. | G16: Visual Check (L 5) at room temperature Need to meet the requirements of L5 in Testing Evaluation | H16: The DUT shall be in sleep mode or if there is no sleep mode powered OFF during the temperature transition and stabilisation phases.
A17: 6 | B17: K6 Power Thermal Cycle | C17: EE-HWRD-HUD3-1432 TPJLR.18.125（Issue 5） Section K6 ISO 16750-4:2010 Section 5.3.1 IEC 60068-2-14:2009 (Test Nb) | D17: Expose the DUTs for 30 cycles,run the profile in Figure 1/Table 2（EE-HWRD-HUD3-1432） Tmin：-40℃/Tmax:85℃ power cycle:1 minute on - 4 minutes off Monitored operation as described in L 3 shall be performed in the operational sections. Component operation shall be cycled between Normal Load Stress and Maximum Load Stress. When the test is complete perform the Functional and the Visual Check as specified in L 2 and L 5 at TN | E17: When the test is complete perform the Functional Check (L 2) at TN, Need to meet the requirements of L2 in Testing Evaluation. | F17: When the supply voltage of the DUT is within the normal operating voltage range, the DUT should meet the requirements of L3. | G17: Visual Check (L 5) at room temperature Need to meet the requirements of L5 in Testing Evaluation
A18: 7 | B18: K7 Thermal Shock in Air | C18: TPJLR.18.125（Issue 5） Section K7 ISO 16750-4:2010 Section 5.3.2 IEC 60068-2-14:2009 Test Na | D18: The DUTs shall be unpowered. Bring both chambers to their respective set temperatures -40℃TEmin and 95℃ TEmax as indicated in Figure 3. Move the DUT’s into the cold chamber within 30s and start the cold soak cycle. Soak the DUTs for 30 min. Move the DUTs into the hot chamber within 30 seconds and begin the hot soak cycle. Soak the DUTs for 30 minutes.The test cycles：300 When the test is complete perform the Functional and the Visual Check as specified in L 2 and L 5 at TN | E18: When the test is complete perform the Functional Check (L 2) at TN, Need to meet the requirements of L2 in Testing Evaluation. | F18: / | G18: Visual Check (L 5) at room temperature Need to meet the requirements of L5 in Testing Evaluation
A19: 8 | B19: K8 Dewing Test | C19: TPJLR.18.125（Issue 5） Section K8 ISO 16750-4:2010 Section 5.6.2.4 Test 3 | D19: a:The supply voltage and current consumption of the DUTs shall be measured and logged throughout the test. b: Complete IEC 60068-2-30 Test Db using the variant in Figure 5. The condensation phase may be shortened if required to maintain a difference of 1 °C to 2 °C between the surface of the DUT and the chamber to ensure that condensation forms on its surface. c: During the condensation phase the ambient temperature of the chamber shall be controlled by heating the water in the bath/floor trough. The temperature difference between the water bath and the ambient temperature of the chamber must always be <15 °C. The test chamber wall temperature must be higher than the DUT temperature. d: A short functional test at 13.5 V ±0.2 V (between 15 seconds and 2 minutes duration) shall be performed on the DUTs every 10 °C rise in temperature (at 30 °C, 40 °C, 50 °C, 60 °C) as shown in Figure 5. e: A long functional test at 13.5 V ± 0.2 V shall start when the DUTs reach 70 °C and continue for 15 minutes after reaching 80 °C. f: After the condensation phase switch to chamber temperature control and maintain the chamber temperature at 80 °C for 45 minutes. g: During the drying phase switch off the water bath heater and use the chamber temperature control to return the temperature to initial conditions (20 °C ±3 °C) over a 90 minute period. h: Repeat from c for 5 cycles. | E19: In addition to the requirements of L2, the output values of the following devices need to be measured： 3.3V for MCU (C4012): 3.3±0.18V; 1.15V for Deserializer (C9498): 1.15±0.06V; 1.8V for Deserializer (C4201): 1.8±0.11V; Motor Driver(C8521): 13.5±1.5V; | F19: 1. During the test, when functional verification is not required, the HUD should be in a sleep state (at 12 V ± 0.2 V)and the sleep current should be monitored throughout the process. 2. A short functional test as L3 at 13.5 V ±0.2 V (between 15 seconds and 2 minutes duration) shall be performed on the DUTs every 10 °C rise in temperature (at 30 °C, 40 °C, 50 °C, 60 °C) ; A long functional test as L3 at 13.5 V ± 0.2 V shall start when the DUTs reach 70 °C and continue for 15 minutes after reaching 80 °C. ---Only the current values (operating current and sleep current) and software monitoring are required for the test. 3. Test placement of DUT: Two of the DUTs shall be installed horizontally (with primary side up), two inverted (with primary side down) and the final two DUTs shall be oriented as installed in the vehicle | G19: Visual Check (L 5) at room temperature. Need to meet the requirements of L5 in Testing Evaluation
A20: 9 | B20: K9 Temperature/Humidity Cycle | C20: TPJLR.18.125（Issue 5） Section K9 ISO 16750-4 Section 5.6.2.3 IEC 60068-2-38 Test Z/AD | D20: The DUTs shall then be subjected to the temperature/humidity cycle shown in Figure 6.During this cycle, the DUTs shall be in Sleep mode if available (at 12 V±0.2 V) or switched off.The DUT shall be powered on and a short Functional Check (L 2). performed during that last hour of each cycle. The temperature/humidity cycle shall be repeated for 10 cycles There shall be a final 24 h drying period as specified in IEC 60068-2-38 Test Z/AD When the test is complete return the temperature to TN and perform the Functional Check (L 2) and Visual Check (L 5) | E20: The DUT shall be powered on and a short Functional Check (L 2); When the test is complete perform the Functional Check (L 2) at Ttest. Need to meet the requirements of L2 in Testing Evaluation. | F20: / | G20: Visual Check (L 5) at room temperature. Need to meet the requirements of L5 in Testing Evaluation.
A21: 10 | B21: K10 Water\Fluid Ingress Test | C21: TPJLR.18.125（Issue 5） Section K10 ISO 20653 | D21: EE-HWRD-HUD3-1447: The Drip test procedure for HUD shall follow that defined in ISO 20653 for an IP Rating of IP5K2；DUT should be operational during the test. Repeat the test for each mounting orientation. | E21: When the test is complete perform the Functional Check (L 2) at TN. Need to meet the requirements of L2 in Testing Evaluation. | F21: 1. The DUT needs to be operated according to the requirements of L3 during the test. 2. Lab should mount the DUTs at the same orientation as used in the vehicle and the test surface is the cover lens, then turn the DUT to test in all four directions (keep the test surface as a cover lens). 3. No need to add a sensor monitoring system to the test | G21: Visual Check (L 5) at room temperature. Need to meet the requirements of L5 in Testing Evaluation.
A22: 11 | B22: K13 Dust Ingress | C22: TPJLR.18.125（Issue 5） Section K13 ISO 20653:2013 Section 8.3 (IP5KX, IP6KX) | D22: Test dust A2 according to ISO 12103-1 (Arizona dust) shall be used. Prior to the test, DUTs shall be stabilised to the temperature and humidity test conditions for at least 24 hours. Operating Mode: DUT shall be operating according to Monitored Operation (L 3). IP :IP5K;Number of Cycles: 20 | E22: When the test is complete perform the Functional Check (L 2) at TN. Need to meet the requirements of L2 in Testing Evaluation. | F22: Lab should mount the DUTs at the same orientation as used in the vehicle. DUT shall be operating according to Monitored Operation (L 3) No need to add a sensor monitoring system to the test | G22: Visual Check (L 5) at room temperature. Need to meet the requirements of L5 in Testing Evaluation.
A23: 12 | B23: K14 Dust Blowing Test | C23: TPJLR.18.125（Issue 5） Section K14 IEC 60068-2-68 | D23: Temperature: 25 °C to 35 °C. Dust Concentration: 0.1 g/m³ to 0.3 g/m³. Dust Velocity: 2.5 m/s ±0.5 m/s. Relative Humidity: 0-30 % RH Arizona dust Operating Mode: DUT shall be operating according to Monitored Operation (L 3). Perform the test for 1 hour； Wipe or shake off excess dust and perform the Functional Check (L 2) and Visual Check (L 5).Repeat 3 times | E23: When the test is complete perform the Functional Check (L 2) at TN. Need to meet the requirements of L2 in Testing Evaluation. | F23: Lab should mount the DUTs at the same orientation as used in the vehicle. DUT shall be operating according to Monitored Operation (L 3) No need to add a sensor monitoring system to the test | G23: Visual Check (L 5) at room temperature. Need to meet the requirements of L5 in Testing Evaluation.
A24: 13 | B24: K15 Vibartion | C24: TPJLR.18.125（Issue 5） Section K15 ISO 16750-3 IEC 60068-2-6 (Test Fc) IEC 60068-2-64 | D24: Operating Mode: DUT shall be operating K 15.3.1 Body Mounted (Sprung mass) Test temperature according to Fig. 7 Tmin：-40℃/Tmax:85℃ Random Wide-Band Random Vibration excitation according to IEC 60068-2-64 using the profile in Figure 8. Test duration is 8 hours for each axis with RMS acceleration value of 30.8 m/s2. When the test is complete perform the Functional Check and Visual Check as specified in sections L 2 and L 5. | E24: When the test is complete perform the Functional Check (L 2) at TN. Need to meet the requirements of L2 in Testing Evaluation. | F24: When the supply voltage of the DUT is within the normal operating voltage range, the DUT should meet the requirements of L3. No need to add a sensor monitoring system to the test | G24: Visual Check (L 5) at room temperature. Need to meet the requirements of L5 in Testing Evaluation.
A25: 14 | B25: K16 Mechanical Shock/Drop | C25: TPJLR.18.125（Issue 5） Section K16.1 EE-HWRD-HUD3-1457/1458 | D25: K 16.1 Package Drop. Drop the package a distance of 1m onto a concrete or steel surface. Repeat once for each package surface and corner. When the test is complete open the package and perform the Functional Check and Visual Check as specified in sections L 2 and L 5. | E25: When the test is complete perform the Functional Check (L 2) at TN. Need to meet the requirements of L2 in Testing Evaluation. | F25: / | G25: Visual Check (L 5) at room temperature. Need to meet the requirements of L5 in Testing Evaluation. | H25: There are a total of 14 samples in this project, 6 samples tested 6 different package surfaces, and the other 8 samples tested different package corners.
A26: 15 | C26: TPJLR.18.125（Issue 5） Section K16.4 EE-HWRD-HUD3-1457/1458 | D26: K 16.4 Low Mechanical Shock. Expose the DUTs to 10 ms half-sine shock impulses of 491 m/s² (50 g), one in each opposite direction of each perpendicular axis. When the test is complete perform the Functional Check and Visual Check as specified in sections L 2 and L 5. | E26: When the test is complete perform the Functional Check (L 2) at TN. Need to meet the requirements of L2 in Testing Evaluation. | F26: When the supply voltage of the DUT is within the normal operating voltage range, the DUT should meet the requirements of L3. No need to add a sensor monitoring system to the test | G26: Visual Check (L 5) at room temperature. Need to meet the requirements of L5 in Testing Evaluation.
A27: 16 | B27: K17 Audible Noise | C27: TPJLR.18.125（Issue 5） Section K17 TPJLR.00.187 (Issue 2) | D27: Static (Load Deflection and Noise) Test: The whole HUD is at a static state, the motor does not rotate The component or assembly to be tested must be attached to a sufficiently stiff frame or part body shell in the same orientation as it is within the vehicle, using the same attachment / fixing points and methods;Ambient temperature for the purpose of this test must be at 21°C ±3°C Audio recordings shall be supplied to the JLR NVH PAT leader. | E27: Subjective:≥VER 7(TPJLR.00.201)
A28: 17 | D28: Shaker Test: The entire HUD is in a state of mechanical vibration and the Motor does not rotate The component or assembly to be tested must be attached to a sufficiently stiff frame or part body shell in the same orientation as it is within the vehicle, using the same attachment / fixing points and methods;Ambient temperature for the purpose of this test must be at 21°C ±3°C The continuous duration of the test must be a minimum of 15 minutes in TPJLR.00.187 Appendix C
A29: 18 | B29: K18 Connector and lead/lock strength | C29: TPJLR.18.125（Issue5） Section K18 | D29: K 18.1 Connector Push Test Apply 1.5 times the Rated Maximum Engagement force to the connector in the direction of mating for one minute. Connector 1 (7pin): 29.4N Connector 2 (3pin): 20N | E29: When the test is complete perform the Functional Check (L 2) at TN. Need to meet the requirements of L2 in Testing Evaluation. | F29: / | G29: Visual Check (L 5) at room temperature. Need to meet the requirements of L5 in Testing Evaluation. | H29: K18.1: During the test, two samples are to be selected and pressure transducers are to be placed at the specified locations and monitored during the test ensure that no component exceeds 50% of its specified maximum strain or 500 microstrain, whichever is the lower
A30: 19 | D30: K 18.2 Connector Torque Test. Independently apply 39.2 N (4 kgf) to all four sides of the harness connector(s), perpendicular to the direction of mating, at the greatest moment arm of each axis, for one minute.
A31: 20 | D31: K 18.3 Connector Durability Test. Plug and unplug each connection system 11 times by hand or use the maximum specified torque if a bolt is required. The time to mate each connection system by hand must not exceed 4s .
A32: 21 | D32: K 18.4 Lead/Lock Pull Test a If DUT has individual wire(s) pull each as follows: • to 0.3 mm²: 49 N • >0.3 mm² to 0.5 mm²: 78.5 N b If DUT has a wire bundle pull the wire bundle: 98.1 N
A33: 22 | B33: K20 Solar Radiation | C33: TPJLR.18.125（Issue5） Section K20 IEC 60068-2-5 | D33: Test method: Sa 2 1cycle，24h：20h irradiation, 4h darkness Irradiance：21.8kWh/m2 per diurnal cycle； total 1 cycle； low temperature （darkness）：25℃ upper temperature （irradiation）：40℃ Tests shall be performed on assembled module. | E33: When the test is complete perform the Functional Check (L 2) at TN. Need to meet the requirements of L2 in Testing Evaluation. | F33: / | G33: Visual Check (L 5) at room temperature. Need to meet the requirements of L5 in Testing Evaluation.
A34: 23 | B34: K21 Corrosive Gases | C34: TPJLR.18.125（Issue5） Section K21 IEC 60068-2-60 Test Ke Method 4 | D34: EE-HWRD-HUD3-1618: Complete the test according to IEC 60068-2-60 Test Ke Method 4 with the following parameters: The test shall be run over 1000 hours at a temperature of 60°C and RH of 95% Gas Concentration: H2S (Hydrogen Sulphide) concentration shall be 1000 ppb (±5) SO2 (Sulphur Dioxide) concentration shall be 2000 ppb (±20) CL2(Chlorine) concentration shall be10ppb (±5) NO2(Nitrogen Dioxide) concentration shall be 200 ppb (±20) Once the test is complete perform a Functional Check and the Visual Check as per sections L 2 and L 5 | E34: When the test is complete perform the Functional Check (L 2) at TN. Need to meet the requirements of L2 in Testing Evaluation. | F34: / | G34: Visual Check (L 5) at room temperature. Need to meet the requirements of L5 in Testing Evaluation.
A35: 24 | B35: K22 Chemical Resistance | C35: TPJLR.18.125（2022） Section K22 STJLR.18.233（2021）G9 ISO 16750-5:2011 | D35: EE-HWRD-HUD3-1468 Tests shall be performed on assembled module,Only test the cover lens part (The HUD is installed in the IP station, only the cover lens will be exposed in the cockpit, and the rest are hidden) Test Temp:Tn; Test Duration:96h 1. Denatured Alcohol--I 2. Glass Cleaner--I 3. Ammonia Containing Cleaner --II 4. Leather Wax --II 5. Deodorizer Spray --I 6. Interior Cleaners --I 7. Acetone-- I 8. Perspiration--II 9. Cosmetic Products eg Creams/Moisturisers--II 10. Refreshment containing Sugar & Caffeine--III 11. Cream, Coffee Whitener--III | E35: When the test is complete perform the Functional Check (L 2) at TN. Need to meet the requirements of L2 in Testing Evaluation. | F35: / | G35: Visual Check (L 5) at room temperature. Need to meet the requirements of L5 in Testing Evaluation.
A36: 25 | B36: K23 Thermal Shock Endurance | C36: TPJLR.18.125（Issue 5） Section K23 IEC 60068-2-14 test Na | D36: Test only PCBA Before test：The PCBA must first perform an X-RAY inspection to ensure that the solder quality must meet “Acceptable Class 3” according to IPC-A-610 for all sections applicable to the PCBA, including no evidence of large solder voids (30% or greater F 8.3.12.4). This test shall not be performed until compliance is met. Soak the DUTs for 30 minutesat temperatures -40℃TEmin and 95℃TEmax The temperature exchange time is 30s Continue to cycle the DUTs for 1,000 cycles, performing a Visual Inspection of the joints and coatings at 320±10, 640 ±10 and 1,000 cycles When the test is complete return DUTs to room temperature. Perform a Performance Evaluation (L 1) and Visual Check (L 5) | E36: Because it is tested by PCBA, when performing L1 verification after the test, LAB need to monitor the current value, the MCU and Signal Transmission in the upper computer software. | F36: / | G36: The PCBA need meet the requirement of L6： Method A to D Methods C and D can select three samples for inspection. No cracks in the solder, no tin whiskers and no cracks or bubbles in coatings allowed. Three of the samples shall have solder joints examined by sectioning and if used previously x-ray. Cracks that interrupt no more than 30% of the solder joint may be accepted at the discretion of the JLR Component Engineer. | H36: 1. Before start of test, submit a copy of the DUT assembly solder profiles (Reflow, Wave, and Selective Solder) to the JLR Component Engineer with written verification that the profiles meet the solder and component manufacturers’ thermal requirements. 2. Where Conformal Coating is used, submit a copy of the curing profile to the JLR Component Engineer (Including UV curable coatings) and written verification this meets the manufacturers’ requirements. 3. Provide pictures of all cross sections and a representative number of each joint type.
A37: 26 | B37: K24 High Temperature Endurance | C37: TPJLR.18.125（Issue 5） Section K24 IEC 60068-2-2 Test Be | D37: Power up chamber and stabilize at the specified temperature 85℃Tmax/Tpma. Expose the DUTs for 1,000 hours whilst performing Monitored Operation as specified in section L 3. Check the DUTs once per day to verify that they are operating properly. When the test is complete perform the Functional and Visual Check as specified in sections L 2 and L 5. | E37: When the test is complete perform the Functional Check (L 2) at Ttest. Need to meet the requirements of L2 in Testing Evaluation. | F37: Check the DUTs once per day to verify that they are operating properly. The DUT should meet the requirements of L3. | G37: Visual Check (L 5) at room temperature. Need to meet the requirements of L5 in Testing Evaluation.
A38: 27 | B38: K26 Mechanical Wear-Out | C38: TPJLR.18.125（Issue 5） Section K26 | D38: EE-HWRD-HUD3-1480 The HUD module shall be tested by rotating the HUD movable mirror from one end of travel to another, and back again. This shall be deemed as one cycle. 100000 cycles at TN 25000 cycles at Tmin/Tpmin 25000 cycles at Tmax/Tpmax When the test is complete return DUTs to room temperature and perform the Functional and Visual Check as specified in sections L 2 and L 5. | E38: When the test is complete perform the Functional Check (L 2) at Ttest. Need to meet the requirements of L2 in Testing Evaluation. | F38: DUT shall be operating according to Monitored Operation (L 3) | G38: Visual Check (L 5) at room temperature. Need to meet the requirements of L5 in Testing Evaluation. | H38: Functional tests shall confirm that all optical requirements (with particular attention paid to image position) are met. Image position at the end of the test shall not less than 2m, as measured at the system Virtual Image Distance.--Based on current experience, the deviation of the virtual image distance between the test and the test is less than 2mm, so this item can only be modified to ensure that the virtual image distance after the test is greater than 2m.
A39: 28 | B39: K27 85/85High Temperature -High Humidity Endurance | C39: TPJLR.18.125（Issue 5） Section K27 | D39: 85℃，85%RH 1000h Check the DUTs once per day to verify that they are operating properly When the test is complete return DUTs to room temperature and perform the Functional and Visual Check as specified in sections L 2 and L 5. | E39: When the test is complete perform the Functional Check (L 2) at Ttest. Need to meet the requirements of L2 in Testing Evaluation. Abnormality and damage to the TFT are allowed. | F39: DUT shall be operating according to Monitored Operation (L 3) Abnormality and damage to the TFT are allowed | G39: Visual Check (L 5) at room temperature. Need to meet the requirements of L5 in Testing Evaluation.
A40: 29 | D40: 60℃，95%RH 1100h Check the DUTs once per day to verify that they are operating properly When the test is complete return DUTs to room temperature and perform the Functional and Visual Check as specified in sections L 2 and L 5. | E40: When the test is complete perform the Functional Check (L 2) at Ttest. Need to meet the requirements of L2 in Testing Evaluation. | F40: DUT shall be operating according to Monitored Operation (L 3) | G40: Visual Check (L 5) at room temperature. Need to meet the requirements of L5 in Testing Evaluation.
A41: 30 | B41: K28 HALT | C41: TPJLR.18.125（Issue 5） Section K28 | D41: Operational limit tests：3 samples Conduct the Performance Evaluation test, L 1, on the DUTs before starting the test and on surviving DUTs at the end of testing. Cold test.：Reduce temperature to -40 °C at a maximum rate of 4 °C/min. Power up DUT and verify proper operation. Power off and lower the temp in 5 °C increments with a 5 minute dwell. After each dwell power up and verify proper operation. Continue until improper operation is found or -100 °C is reached. Hot test.:Raise temperature to +75 °C at 4 °C/min max. Power up module and verify proper operation. Power off and raise the temp in 5 °C increments with a 5 minute dwell. After each dwell power up and verify proper operation. Continue until improper operation is found or until Tmax +50 °C is reached. | E41: Two batches of samples（3+3） are undergoing HOT testing (one with the official PV software version, and the other with the software version that has the TFT over-temperature protection removed).
D42: Thermal Shock test. Conduct the Performance Evaluation test, L 1, on the DUTs before starting the test and on surviving DUTs at the end of testing. Reduce temperature to -40 °C at 4 °C/min. max. Power up module and verify proper operation. Start the thermal shock test with a ramp rate of 15 °C/min to T6 and dwell for as long as it takes the board to come to temperature and then power off the module and return to -40 °C. Repeat this temp/power on & off cycle 5 times. Increase the ramp rate in 5 °C/min increments and repeat the 5 cycles until a module fails or the ramp rate equals 50 °C/min.
...

Sheet Testing Evaluation
A4: TPJLR.18.125
A5: Item | B5: Method | E5: Acceptance
A6: L1 Performance Evaluation | B6: Appearance Check | C6: 1. Cover lens:Fit well, no scratches, discolouration, warping, peeling and other anomalies. 2. Appearance of other parts: no deformation, burr, discolouration, cracking and other abnormalities. 3. Labels: labels are well pasted, no peeling off phenomenon; label handwriting is clearly visible. 4. Shake the sample machine to confirm that the internal PCB components are not loose - no abnormal noise. 5.Confirm the appearance of the surface of the connector and the internal terminal surface - no deformation, cracking and other defects on the internal and external surfaces of the connector; no oxidation, rust and other defects on the surface of the terminals that affect the function.
B7: Optical test | C7: STJLR.13.5009 TPJLR-13-001 | E7: see optical test sheet
B8: Verify separately according to the voltage and temperature requirements shown in the figure： (After the temperature is stable for 30 minutes, then verify the power-up function of the DUT) TPmax：85℃ Tpmin：-30℃ TN：20℃ Vpmin：9V ±0.2 V Vpmax：16 ±0.2 V VN：13.5 ±0.5 V | C8: Image display | D8: Visual observation: the HUD displays different UIs through the video box. During the test, the tester is required to visually display the image of the sample at all times. | E8: Each UI should be displayed normally without incomplete display, flickering, colour deviation and other abnormalities.
C9: Operating current | D9: After the temperature is stabilised, the HUD is tested at different voltages according to the requirements and the current values of the samples are recorded. Please note that the current value is recorded after the HUD has entered a steady power throttling state upon the ambient temperature reaching 85°C. | E9: Current value (A)--PWM 68%: 1.15±10%(85℃,9V); 0.63±10%(85℃,16V); 1.65±10%(-30℃,9V); 0.85±10%(-30℃,16V) 1.00±10%(20℃,13.5V)
C10: Static Current | D10: Disconnect the enable line to let the HUD go to sleep | E10: <100μA
C11: Brightness | D11: Brightness adjustment: Adjust the brightness (PWM) of the screen through the input signal, the screen can be normally bright and dark (the greater the value of the brightness level, the brighter the screen) | E11: The real-time PWM value must be consistent with the input value.
C12: Image height | D12: Image height adjustment: The Primary Mirror is rotated by sending signals to the motor of the HUD through the operating host computer. | E12: The real-time gears must be consistent with the input value.
C13: Software monitoring | D13: FPD link： Determine if the communication between the HUD and the video box is normal by reading the register state. | E13: The upper computer real-time display of the current state, can not travel to report errors.
D14: IIC： video box can Set the heartbeat rate for instance, if the heartbeat is set by 100ms , it will be report the failure of heartbeat loss in 300ms | E14: The upper computer real-time display of the current state, can not travel to report errors.
D15: Display ： Reading and logging HUD faults& reconfigurations&TFT temperature by logging video box's UART logs | E15: It is possible to store logs to the PC and confirm them after the test, and whether an error report has occurred during the test. (Need to exclude human operation situations, such as re-powering the HUD, etc.)
A16: L2 Functional Check | B16: a. Operate the DUT at Function Check Test Voltage VN (13.5 ±0.5 V) and Confirm whether the current value, PWM value, motor and image are normal at either room temperature TN or test chamber set temperature. b. Operate the DUT as required on the right. Record any discrepancies or abnormal operation. c. Functional Checks shall be performed immediately after or within 24 hours following each environmental test as appropriate and/or as specified. | C16: Image display | D16: Visual observation: the HUD displays different UIs through the video box. | E16: Each UI should be displayed normally without incomplete display, flickering, colour deviation and other abnormalities.
C17: Brightness | D17: Brightness adjustment: Adjust the brightness (PWM) of the screen through the input signal, the screen can be normally bright and dark (the greater the value of the brightness level, the brighter the screen) | E17: The real-time PWM value must be consistent with the input value.
D18: Brightness change monitoring Three brightness sensors are placed on the surface of the cover lens of the HUD to obtain the brightness value in real time. The value of sensor 2 is used to confirm whether the HUD backlight is in operation and the change of brightness(The upper computer can record changes in brightness throughout the test period.) | E18: In the upper computer, the value of the sensor 2 cannot change during the test (changes that occur during the test when there is human interference with the ambient brightness are not considered anomalous).
C19: Image height | D19: Image height adjustment: The Primary Mirror is rotated by sending signals to the motor of the HUD through the operating host computer. | E19: The real-time gears must be consistent with the input value.
D20: Motor rotation monitoring (For HUD in the temperature chamber only): Three brightness sensors are placed on the surface of the cover lens of the HUD to obtain the brightness value in real time. The difference between sensors 1 and 3, the maximum and minimum values can be used to confirm whether the motor is in the highest and lowest gear .(The upper computer can record changes in brightness throughout the test period.) | E20: The Primary Mirror When rotating to the highest and lowest positions, the values of sensor 1 and sensor 2 in the upper computer should be the same as the values calibrated before the test, and it can be regarded that the motor has completed the rotation.
C21: Software monitoring | D21: FPD link： Determine if the communication between the HUD and the video box is normal by reading the register state. | E21: 1. The upper computer real-time display of the current state, can not travel to report errors 2. It is possible to store logs to the PC and confirm them after the test, and whether an error report has occurred during the test. (Need to exclude human operation situations, such as re-powering the HUD, etc.)
D22: IIC： video box can Set the heartbeat rate for instance, if the heartbeat is set by 100ms , it will be report the failure of heartbeat loss in 300ms | E22: 1. The upper computer real-time display of the current state, can not travel to report errors 2. It is possible to store logs to the PC and confirm them after the test, and whether an error report has occurred during the test. (Need to exclude human operation situations, such as re-powering the HUD, etc.)
D23: Display ： Reading and logging HUD faults& reconfigurations&TFT temperature by logging video box's UART logs | E23: It is possible to store logs to the PC and confirm them after the test, and whether an error report has occurred during the test. (Need to exclude human operation situations, such as re-powering the HUD, etc.)
A24: L3 Monitored Operation | B24: a. If there are no special requirements of the standard, the test voltage is 13.5V. b. Set the PWM value to XX% before the test. c. Monitor the functional requirements on the right. | C24: Image display | D24: Visual observation: the HUD displays different UIs through the video box. Laboratory personnel are required to perform image confirmation at three fixed periods per day during working days and two periods per day on non-working days | E24: Each UI should be displayed normally without incomplete display, flickering, colour deviation and other abnormalities.
C25: Brightness | D25: Brightness adjustment: Adjust the brightness (PWM) of the screen through the input signal, the screen can be normally bright and dark (the greater the value of the brightness level, the brighter the screen) | E25: The real-time PWM value must be consistent with the input value.
D26: Brightness change monitoring Three brightness sensors are placed on the surface of the cover lens of the HUD to obtain the brightness value in real time. The value of sensor 2 is used to confirm whether the HUD backlight is in operation and the change of brightness(The upper computer can record changes in brightness throughout the test period.) | E26: In the upper computer, the value of the sensor 3 cannot change during the test (changes that occur during the test when there is human interference with the ambient brightness are not considered anomalous). The lab needs to confirm the data on a daily basis that the brightness of the HUD has changed and that the HUD is on/off as expected.
C27: Image height | D27: Image height adjustment: The Primary Mirror is rotated by sending signals to the motor of the HUD through the operating host computer. | E27: The real-time gears must be consistent with the input value.
D28: Motor rotation monitoring (For HUD in the temperature chamber only): Three brightness sensors are placed on the surface of the cover lens of the HUD to obtain the brightness value in real time. The difference between sensors 1 and 3, the maximum and minimum values can be used to confirm whether the motor is in the highest and lowest gear .(The upper computer can record changes in brightness throughout the test period.) | E28: The Primary Mirror When rotating to the highest and lowest positions, the values of sensor 1 and sensor 2 in the upper computer should be the same as the values calibrated before the test, and it can be regarded that the motor has completed the rotation.
C29: Software monitoring | D29: FPD link： Determine if the communication between the HUD and the video box is normal by reading the register state. | E29: 1. The upper computer real-time display of the current state, can not travel to report errors 2. It is possible to store logs to the PC and confirm them after the test, and whether an error report has occurred during the test. (Need to exclude human operation situations, such as re-powering the HUD, etc.)
D30: IIC： video box can Set the heartbeat rate for instance, if the heartbeat is set by 100ms , it will be report the failure of heartbeat loss in 300ms | E30: 1. The upper computer real-time display of the current state, can not travel to report errors 2. It is possible to store logs to the PC and confirm them after the test, and whether an error report has occurred during the test. (Need to exclude human operation situations, such as re-powering the HUD, etc.)
D31: Display ： Reading and logging HUD faults& reconfigurations&TFT temperature by logging video box's UART logs | E31: It is possible to store logs to the PC and confirm them after the test, and whether an error report has occurred during the test. (Need to exclude human operation situations, such as re-powering the HUD, etc.)
A32: L4 Functional Evaluation | B32: Verify separately according to the voltage and temperature requirements shown in the figure： (After the temperature is stable for 30 minutes, then verify the power-up function of the DUT) Tmax：85℃ Tmin：-40℃ Vmin：7.5V ±0.2 V Vmax：16 ±0.2 V | C32: Image display | D32: Visual observation: the HUD displays different UIs through the video box. During the test, the tester is required to visually display the image of the sample at all times. | E32: Each UI should be displayed normally without incomplete display, flickering, colour deviation and other abnormalities. When the voltage is 7.5V, no display.
C33: Operating current | D33: After the temperature is stabilised, the HUD is tested at different voltages according to the requirements and the current values of the samples are recorded. Please note that when the test voltage is 7.5V, the HUD INPUT terminal needs to be measured, and the power supply should be adjusted to ensure the voltage at the HUD terminal reads 7.5V. Please note that the current value is recorded after the HUD has entered a steady power throttling state upon the ambient temperature reaching 85°C. | E33: Current value (A): 0.72±10%(85℃,7.5V); PWM 10% 0.63±10%(85℃,16V);PWM 68% 0.68±10%(-40℃,7.5V);PWM 10% 0.87±10%(-40℃,16V) PWM 68%
C34: Static Current | D34: Disconnect the enable line to let the HUD go to sleep | E34: <100μA
C35: Brightness | D35: Brightness adjustment: Adjust the brightness (PWM) of the screen through the input signal, the screen can be normally bright and dark (the greater the value of the brightness level, the brighter the screen) | E35: The real-time PWM value must be consistent with the input value.
C36: Image height | D36: Image height adjustment: The Primary Mirror is rotated by sending signals to the motor of the HUD through the operating host computer. | E36: The real-time gears must be consistent with the input value.
C37: Software monitoring | D37: FPD link： Determine if the communication between the HUD and the video box is normal by reading the register state. | E37: The upper computer real-time display of the current state, can not travel to report errors.
D38: IIC： video box can Set the heartbeat rate for instance, if the heartbeat is set by 100ms , it will be report the failure of heartbeat loss in 300ms | E38: The upper computer real-time display of the current state, can not travel to report errors.
D39: Display ： Reading and logging HUD faults& reconfigurations&TFT temperature by logging video box's UART logs | E39: It is possible to store logs to the PC and confirm them after the test, and whether an error report has occurred during the test. (Need to exclude human operation situations, such as re-powering the HUD, etc.)
A40: L5 Visual Check | B40: a. Examine the HUD for visible signs of deterioration or damage. b. Photograph the sample from all applicable angles. Photographs shall be retained and may be included in test reports if applicable. c. Visual Checks shall be performed immediately after or 24 hours following each environmental test as appropriate and/or as specified. | D40: a. Good appearance quality, the surface of the paint film should be uniform and free of bubbles, burrs, build-up and overflow; plastic parts should be free of cracks and deformation that affect function and appearance; b. The cover lens should not have obvious colour difference before and after the test; c. The metal middle housing (non-internal paint level) is allowed to have changes in gloss and corrosion, but no problems affecting the assembly. d. HUD component parts are connected tightly, no loose, loose phenomenon; shaking the HUD can not appear abnormal sound. e. HUD shell on the appearance of the label paper should be no abnormality, there shall be no shedding, font is not clear and other phenomena.
A41: L6 Internal Inspection | B41: One sample is taken after the end of a test group to perform the following checks:​ Method A:Take a Photography for the PCBA--Check the entire PCBA； Method B：X-ray--Check the entire PCBA----Check the entire PCBA； Method C（Selected project）：SEM----Check the key pins of the core device Method D（Selected project）：Sectioning analysis----Check the key pins of the core device Group A：A+B Group B：A+B Group C: A+B Group D-1: A+B Group D-2: A+B Group D-3: A+B+C+D Group D-4: A+B Group D-5: A+B Group D-6: A+B | D41: Photography: --Confirm that the surface of the PCBA should be clean, tidy and pollution-free; the screen printing logo should be clear； --The protective coating should not have problems such as foaming, peeling, cracking, etc. X-Ray: --Solder joints: no virtual welding and short circuit; --Connection line: no disconnection, short circuit and other abnormalities; --PCBA: Abnormal conditions such as open circuit, short circuit, hole, etc. cannot occur. SEM:No tin whiskers can appear on solder joints and pins； Sectioning：Microscopic inspection of solder joints, no abnormal problems such as cracking and virtual welding can occur
B42: Core device： RIN0± input (U9402) LVDS Output (U5500) MCU (U9406) Motor Driver (E8501) Additional requirements: Required in addition to the 4 core devices listed above(On the K23 test item, add new requirements): Large packages of resistors, capacitors, inductors, diodes, LEDs and PINs (one PIN for each of the different connectors) to be sliced and analysed for testing.

Sheet optical test
A2: No. | B2: Item | C2: Requirement
A3: 1 | B3: Global rotation | C3: Optimum Control Point: |Rotation| <=0.75°;
C4: Nominal Control Region: |Rotation| <=1.5°;
C5: Extremity Control Region: |Rotation| <=2.5°.
A6: 2 | B6: X-Distortion | C6: Optimum Control Point: |Distortion(X)| <=2.0°;
C7: Nominal Control Region: |Distortion(X)| <=4.0°;
C8: Extremity Control Region: |Distortion(X)| <=7.0°
A9: 3 | B9: Y-Distortion | C9: Optimum Control Point: |Distortion(Y)| <=1.5 °;
C10: Nominal Control Region: |Distortion(Y)| <=1.8°;
C11: Extremity Control Region: |Distortion(Y)| <=2.1°
A12: 4 | B12: Contrast ratio（OCCc） | C12: ≥350:1
A13: 5 | B13: Peak Luminance （OCCUCB） | C13: OCCc ≥12500 cd/m^2
A16: 6 | B16: Uniformity（OCCUCB） | C16: OCCU＞60%
C17: OCCC＞60%
C18: OCCB＞60%
A19: 7 | B19: Look Down Angle（OCCc） | C19: -3°
A20: 8 | B20: FOV-H （OCCUCB） | C20: OCCU: 7.5° ±5%
C21: OCCC: 7.5° ±5%
C22: OCCB: 7.5° ±5%
A23: 9 | B23: FOV-V（OCCUCB） | C23: OCCU: 3.75° ±5%
C24: OCCC: 3.75° ±5%
C25: OCCB: 3.75° ±5%
A26: 10 | B26: VID（OCCUCB） | C26: OCCU＞ 2m
C27: OCCC＞ 2m
C28: OCCB＞2m
A29: 11 | B29: Minimum Luminance （OCCUCB） | C29: OCCc <7 cd/m^2
A32: 12 | B32: Colour performance (Over the cover lens/HUD) | C32: R：0.595,0.350（±0.03）
C33: G：0.335,0.570（±0.03）
C34: B：0.160,0.135（±0.03）
C35: W：0.320,0.350（±0.03）
A36: 13 | B36: Contrast performance (night-time)(OCCC) | C36: ≤0.075cd/m2
A37: 14 | B37: Contrast performance (daytime)(OCCC) | C37: ≤75cd/m2
A38: 15 | B38: Astigmatism performance | C38: Optimum Control Point ≤0.25 dioptres
C39: Nominal Control Region ≤0.25 dioptres
C40: Extremity Control Region ≤0.25 dioptres
A41: 16 | B41: Image sharpness | C41: Optimum Control Point >50%
C42: Nominal Control Region >45%
C43: Extremity Control Region >35%
A44: Camera position
